{
 "cells": [
  {
   "cell_type": "code",
   "execution_count": 1,
   "metadata": {},
   "outputs": [
    {
     "name": "stdout",
     "output_type": "stream",
     "text": [
      " * Serving Flask app '__main__' (lazy loading)\n",
      " * Environment: production\n",
      "\u001b[31m   WARNING: This is a development server. Do not use it in a production deployment.\u001b[0m\n",
      "\u001b[2m   Use a production WSGI server instead.\u001b[0m\n",
      " * Debug mode: off\n"
     ]
    },
    {
     "name": "stderr",
     "output_type": "stream",
     "text": [
      " * Running on http://127.0.0.1:5000/ (Press CTRL+C to quit)\n",
      "127.0.0.1 - - [24/Feb/2022 15:34:19] \"GET /add HTTP/1.1\" 405 -\n",
      "[2022-02-24 15:34:23,049] ERROR in app: Exception on / [GET]\n",
      "Traceback (most recent call last):\n",
      "  File \"C:\\Users\\pierr\\AppData\\Local\\Programs\\Python\\Python39\\lib\\site-packages\\flask\\app.py\", line 1516, in full_dispatch_request\n",
      "    rv = self.dispatch_request()\n",
      "  File \"C:\\Users\\pierr\\AppData\\Local\\Programs\\Python\\Python39\\lib\\site-packages\\flask\\app.py\", line 1492, in dispatch_request\n",
      "    self.raise_routing_exception(req)\n",
      "  File \"C:\\Users\\pierr\\AppData\\Local\\Programs\\Python\\Python39\\lib\\site-packages\\flask\\app.py\", line 1474, in raise_routing_exception\n",
      "    raise request.routing_exception  # type: ignore\n",
      "  File \"C:\\Users\\pierr\\AppData\\Local\\Programs\\Python\\Python39\\lib\\site-packages\\flask\\ctx.py\", line 376, in match_request\n",
      "    result = self.url_adapter.match(return_rule=True)  # type: ignore\n",
      "  File \"C:\\Users\\pierr\\AppData\\Local\\Programs\\Python\\Python39\\lib\\site-packages\\werkzeug\\routing.py\", line 2042, in match\n",
      "    raise NotFound()\n",
      "werkzeug.exceptions.NotFound: 404 Not Found: The requested URL was not found on the server. If you entered the URL manually please check your spelling and try again.\n",
      "\n",
      "During handling of the above exception, another exception occurred:\n",
      "\n",
      "Traceback (most recent call last):\n",
      "  File \"C:\\Users\\pierr\\AppData\\Local\\Programs\\Python\\Python39\\lib\\site-packages\\flask\\app.py\", line 2073, in wsgi_app\n",
      "    response = self.full_dispatch_request()\n",
      "  File \"C:\\Users\\pierr\\AppData\\Local\\Programs\\Python\\Python39\\lib\\site-packages\\flask\\app.py\", line 1518, in full_dispatch_request\n",
      "    rv = self.handle_user_exception(e)\n",
      "  File \"C:\\Users\\pierr\\AppData\\Local\\Programs\\Python\\Python39\\lib\\site-packages\\flask\\app.py\", line 1386, in handle_user_exception\n",
      "    return self.handle_http_exception(e)\n",
      "  File \"C:\\Users\\pierr\\AppData\\Local\\Programs\\Python\\Python39\\lib\\site-packages\\flask\\app.py\", line 1326, in handle_http_exception\n",
      "    return self.ensure_sync(handler)(e)\n",
      "  File \"C:\\Users\\pierr\\AppData\\Local\\Temp\\ipykernel_14712\\3807674254.py\", line 50, in not_found\n",
      "    resp = json(message)\n",
      "TypeError: 'module' object is not callable\n",
      "127.0.0.1 - - [24/Feb/2022 15:34:23] \"GET / HTTP/1.1\" 500 -\n",
      "127.0.0.1 - - [24/Feb/2022 15:34:33] \"GET /add HTTP/1.1\" 405 -\n",
      "[2022-02-24 15:34:34,127] ERROR in app: Exception on /add/ [GET]\n",
      "Traceback (most recent call last):\n",
      "  File \"C:\\Users\\pierr\\AppData\\Local\\Programs\\Python\\Python39\\lib\\site-packages\\flask\\app.py\", line 1516, in full_dispatch_request\n",
      "    rv = self.dispatch_request()\n",
      "  File \"C:\\Users\\pierr\\AppData\\Local\\Programs\\Python\\Python39\\lib\\site-packages\\flask\\app.py\", line 1492, in dispatch_request\n",
      "    self.raise_routing_exception(req)\n",
      "  File \"C:\\Users\\pierr\\AppData\\Local\\Programs\\Python\\Python39\\lib\\site-packages\\flask\\app.py\", line 1474, in raise_routing_exception\n",
      "    raise request.routing_exception  # type: ignore\n",
      "  File \"C:\\Users\\pierr\\AppData\\Local\\Programs\\Python\\Python39\\lib\\site-packages\\flask\\ctx.py\", line 376, in match_request\n",
      "    result = self.url_adapter.match(return_rule=True)  # type: ignore\n",
      "  File \"C:\\Users\\pierr\\AppData\\Local\\Programs\\Python\\Python39\\lib\\site-packages\\werkzeug\\routing.py\", line 2042, in match\n",
      "    raise NotFound()\n",
      "werkzeug.exceptions.NotFound: 404 Not Found: The requested URL was not found on the server. If you entered the URL manually please check your spelling and try again.\n",
      "\n",
      "During handling of the above exception, another exception occurred:\n",
      "\n",
      "Traceback (most recent call last):\n",
      "  File \"C:\\Users\\pierr\\AppData\\Local\\Programs\\Python\\Python39\\lib\\site-packages\\flask\\app.py\", line 2073, in wsgi_app\n",
      "    response = self.full_dispatch_request()\n",
      "  File \"C:\\Users\\pierr\\AppData\\Local\\Programs\\Python\\Python39\\lib\\site-packages\\flask\\app.py\", line 1518, in full_dispatch_request\n",
      "    rv = self.handle_user_exception(e)\n",
      "  File \"C:\\Users\\pierr\\AppData\\Local\\Programs\\Python\\Python39\\lib\\site-packages\\flask\\app.py\", line 1386, in handle_user_exception\n",
      "    return self.handle_http_exception(e)\n",
      "  File \"C:\\Users\\pierr\\AppData\\Local\\Programs\\Python\\Python39\\lib\\site-packages\\flask\\app.py\", line 1326, in handle_http_exception\n",
      "    return self.ensure_sync(handler)(e)\n",
      "  File \"C:\\Users\\pierr\\AppData\\Local\\Temp\\ipykernel_14712\\3807674254.py\", line 50, in not_found\n",
      "    resp = json(message)\n",
      "TypeError: 'module' object is not callable\n",
      "127.0.0.1 - - [24/Feb/2022 15:34:34] \"GET /add/ HTTP/1.1\" 500 -\n"
     ]
    }
   ],
   "source": [
    "from flask import Flask, request\n",
    "from bson import ObjectId\n",
    "import json\n",
    "import pymongo\n",
    "\n",
    "app = Flask(__name__)\n",
    "\n",
    "client = pymongo.MongoClient(\"mongodb+srv://pierre:root@cluster0.d96eh.mongodb.net/testunit?retryWrites=true&w=majority\")\n",
    "collection = client.testunit\n",
    "db = collection.testunit\n",
    "\n",
    "@app.route('/add', methods=['POST'])\n",
    "def add_user():\n",
    "\t_json = request.json\n",
    "\tmarque = _json['marque']\n",
    "\tmodele = _json['modele']\n",
    "\tprix = _json['prix']\n",
    "\tquery = {\"Marque : \":marque, \"Mod√®le : \":modele, \"Prix : \":prix}\n",
    "\t\t\n",
    "@app.route('/users')\n",
    "def users():\n",
    "\tusers = pymongo.db.user.find()\n",
    "\treturn users\n",
    "\t\t\n",
    "@app.route('/user/<id>')\n",
    "def user(id):\n",
    "\tuser = pymongo.db.user.find_one({'_id': ObjectId(id)})\n",
    "\treturn user\n",
    "\n",
    "@app.route('/update', methods=['PUT'])\n",
    "def update_user():\n",
    "\t_json = request.json\n",
    "\tmarque = _json['marque']\n",
    "\tmodele = _json['modele']\n",
    "\tprix = _json['prix']\n",
    "\t\t\n",
    "@app.route('/delete/<id>', methods=['DELETE'])\n",
    "def delete_user(id):\n",
    "\tpymongo.db.user.delete_one({'_id': ObjectId(id)})\n",
    "\tresp = json('User deleted successfully!')\n",
    "\tresp.status_code = 200\n",
    "\treturn resp\n",
    "\t\t\n",
    "@app.errorhandler(404)\n",
    "def not_found(error=None):\n",
    "    message = {\n",
    "        'status': 404,\n",
    "        'message': 'Not Found: ' + request.url,\n",
    "    }\n",
    "    resp = json(message)\n",
    "    resp.status_code = 404\n",
    "\n",
    "    return resp\n",
    "\n",
    "if __name__ == \"__main__\":\n",
    "    app.run()"
   ]
  }
 ],
 "metadata": {
  "interpreter": {
   "hash": "60b51427f979fa642d0033feef923a8722499a3dd60fba6b33cc7fbc8e3730d0"
  },
  "kernelspec": {
   "display_name": "Python 3.9.9 64-bit",
   "language": "python",
   "name": "python3"
  },
  "language_info": {
   "codemirror_mode": {
    "name": "ipython",
    "version": 3
   },
   "file_extension": ".py",
   "mimetype": "text/x-python",
   "name": "python",
   "nbconvert_exporter": "python",
   "pygments_lexer": "ipython3",
   "version": "3.9.9"
  },
  "orig_nbformat": 4
 },
 "nbformat": 4,
 "nbformat_minor": 2
}
